[0m14:13:46.245719 [debug] [MainThread]: Sending event: {'category': 'dbt', 'action': 'invocation', 'label': 'start', 'context': [<snowplow_tracker.self_describing_json.SelfDescribingJson object at 0x0000029865B66900>, <snowplow_tracker.self_describing_json.SelfDescribingJson object at 0x0000029863B4A710>, <snowplow_tracker.self_describing_json.SelfDescribingJson object at 0x0000029866809950>]}


============================== 14:13:46.251534 | 509c1a57-6f5d-43bb-90e5-e51ca4f02c41 ==============================
[0m14:13:46.251534 [info ] [MainThread]: Running with dbt=1.9.4
[0m14:13:46.252268 [debug] [MainThread]: running dbt with arguments {'printer_width': '80', 'indirect_selection': 'eager', 'write_json': 'True', 'log_cache_events': 'False', 'partial_parse': 'True', 'cache_selected_only': 'False', 'profiles_dir': 'C:\\Users\\Satheendra\\.dbt', 'debug': 'False', 'version_check': 'True', 'log_path': 'logs', 'fail_fast': 'False', 'warn_error': 'None', 'use_colors': 'True', 'use_experimental_parser': 'False', 'empty': 'False', 'quiet': 'False', 'no_print': 'None', 'log_format': 'default', 'invocation_command': 'dbt run -s dbt-dag', 'introspect': 'True', 'static_parser': 'True', 'target_path': 'None', 'warn_error_options': 'WarnErrorOptions(include=[], exclude=[])', 'send_anonymous_usage_stats': 'True'}
[0m14:13:46.252794 [error] [MainThread]: Encountered an error:
Runtime Error
  No dbt_project.yml found at expected path C:\Users\Satheendra\dbt-dag\dbt_project.yml
  Verify that each entry within packages.yml (and their transitive dependencies) contains a file named dbt_project.yml
  
[0m14:13:46.253545 [debug] [MainThread]: Command `dbt run` failed at 14:13:46.253444 after 0.13 seconds
[0m14:13:46.253824 [debug] [MainThread]: Sending event: {'category': 'dbt', 'action': 'invocation', 'label': 'end', 'context': [<snowplow_tracker.self_describing_json.SelfDescribingJson object at 0x0000029866BA7360>, <snowplow_tracker.self_describing_json.SelfDescribingJson object at 0x0000029866B23BF0>, <snowplow_tracker.self_describing_json.SelfDescribingJson object at 0x0000029866B0BAC0>]}
[0m14:13:46.254124 [debug] [MainThread]: Flushing usage events
[0m14:13:46.842795 [debug] [MainThread]: An error was encountered while trying to flush usage events
[0m15:42:30.681690 [debug] [MainThread]: Sending event: {'category': 'dbt', 'action': 'invocation', 'label': 'start', 'context': [<snowplow_tracker.self_describing_json.SelfDescribingJson object at 0x000001BE0A196900>, <snowplow_tracker.self_describing_json.SelfDescribingJson object at 0x000001BE0817A710>, <snowplow_tracker.self_describing_json.SelfDescribingJson object at 0x000001BE0AE39950>]}


============================== 15:42:30.690950 | 98089d98-0e0b-41f7-851a-214dde517264 ==============================
[0m15:42:30.690950 [info ] [MainThread]: Running with dbt=1.9.4
[0m15:42:30.692067 [debug] [MainThread]: running dbt with arguments {'printer_width': '80', 'indirect_selection': 'eager', 'write_json': 'True', 'log_cache_events': 'False', 'partial_parse': 'True', 'cache_selected_only': 'False', 'profiles_dir': 'C:\\Users\\Satheendra\\.dbt', 'version_check': 'True', 'debug': 'False', 'log_path': 'logs', 'warn_error': 'None', 'fail_fast': 'False', 'use_colors': 'True', 'use_experimental_parser': 'False', 'empty': 'False', 'quiet': 'False', 'no_print': 'None', 'log_format': 'default', 'static_parser': 'True', 'introspect': 'True', 'invocation_command': 'dbt run', 'target_path': 'None', 'warn_error_options': 'WarnErrorOptions(include=[], exclude=[])', 'send_anonymous_usage_stats': 'True'}
[0m15:42:30.692574 [error] [MainThread]: Encountered an error:
Runtime Error
  No dbt_project.yml found at expected path C:\Users\Satheendra\dbt-dag\dbt_project.yml
  Verify that each entry within packages.yml (and their transitive dependencies) contains a file named dbt_project.yml
  
[0m15:42:30.693602 [debug] [MainThread]: Command `dbt run` failed at 15:42:30.693459 after 0.23 seconds
[0m15:42:30.693997 [debug] [MainThread]: Sending event: {'category': 'dbt', 'action': 'invocation', 'label': 'end', 'context': [<snowplow_tracker.self_describing_json.SelfDescribingJson object at 0x000001BE0B1D7360>, <snowplow_tracker.self_describing_json.SelfDescribingJson object at 0x000001BE0B153BF0>, <snowplow_tracker.self_describing_json.SelfDescribingJson object at 0x000001BE0B13BAC0>]}
[0m15:42:30.694902 [debug] [MainThread]: Flushing usage events
[0m15:42:31.309937 [debug] [MainThread]: An error was encountered while trying to flush usage events
[0m15:45:03.988311 [debug] [MainThread]: Sending event: {'category': 'dbt', 'action': 'invocation', 'label': 'start', 'context': [<snowplow_tracker.self_describing_json.SelfDescribingJson object at 0x000001BA9ED76900>, <snowplow_tracker.self_describing_json.SelfDescribingJson object at 0x000001BA9CD5A710>, <snowplow_tracker.self_describing_json.SelfDescribingJson object at 0x000001BA9FA19950>]}


============================== 15:45:03.995291 | aedb532d-0526-4c5b-8dfb-1ad61e388613 ==============================
[0m15:45:03.995291 [info ] [MainThread]: Running with dbt=1.9.4
[0m15:45:03.996322 [debug] [MainThread]: running dbt with arguments {'printer_width': '80', 'indirect_selection': 'eager', 'write_json': 'True', 'log_cache_events': 'False', 'partial_parse': 'True', 'cache_selected_only': 'False', 'warn_error': 'None', 'version_check': 'True', 'debug': 'False', 'log_path': 'logs', 'fail_fast': 'False', 'profiles_dir': 'C:\\Users\\Satheendra\\.dbt', 'use_colors': 'True', 'use_experimental_parser': 'False', 'empty': 'None', 'quiet': 'False', 'no_print': 'None', 'log_format': 'default', 'invocation_command': 'dbt test', 'introspect': 'True', 'static_parser': 'True', 'target_path': 'None', 'warn_error_options': 'WarnErrorOptions(include=[], exclude=[])', 'send_anonymous_usage_stats': 'True'}
[0m15:45:03.996673 [error] [MainThread]: Encountered an error:
Runtime Error
  No dbt_project.yml found at expected path C:\Users\Satheendra\dbt-dag\dbt_project.yml
  Verify that each entry within packages.yml (and their transitive dependencies) contains a file named dbt_project.yml
  
[0m15:45:03.997506 [debug] [MainThread]: Command `dbt test` failed at 15:45:03.997400 after 0.15 seconds
[0m15:45:03.997794 [debug] [MainThread]: Sending event: {'category': 'dbt', 'action': 'invocation', 'label': 'end', 'context': [<snowplow_tracker.self_describing_json.SelfDescribingJson object at 0x000001BA9FDB7360>, <snowplow_tracker.self_describing_json.SelfDescribingJson object at 0x000001BA9FD2FBF0>, <snowplow_tracker.self_describing_json.SelfDescribingJson object at 0x000001BA9FD1BAC0>]}
[0m15:45:03.998073 [debug] [MainThread]: Flushing usage events
[0m15:45:04.584096 [debug] [MainThread]: An error was encountered while trying to flush usage events
